Workbook
Name HolidayEnd: Holidays!$D$5:$D$34
Name HolidayName: Holidays!$B$5:$B$34
Name HolidayStart: Holidays!$C$5:$C$34

Sheet Dashboard
L1: =IF(ISNUMBER($C$31),$C$31,MONTH(TODAY())) -> 10
B2: TEKNOSYS · TELECOM DW | Release Tracker Dashboard | L2: =IF(ISNUMBER($E$31),$E$31,YEAR(TODAY())) -> 2026
B3: ="Live from the Release Calendar sheet · nothing to fill in here · as of "&TEXT(TODAY(),"dd mmm yyyy") -> Live from the Release Calendar sheet · nothing to fill in here · as of 14 Oct 2026 | L3: =DATE($L$2,$L$1,1) -> 46296
L4: =EOMONTH($L$3,0) -> 46326
B5: OVERALL
B6: TOTAL RELEASES | D6: OPEN | G6: COMPLETED | I6: DUE SOON (≤ 3 DAYS)
B7: =COUNTA('Release Calendar'!B5:B504) -> 37 | D7: =SUMPRODUCT(('Release Calendar'!B5:B504<>"")*('Release Calendar'!M5:M504<>"Completed")) -> 6 | G7: =COUNTIF('Release Calendar'!M5:M504,"Completed") -> 31 | I7: =SUMPRODUCT(('Release Calendar'!B5:B504<>"")*('Release Calendar'!J5:J504<>"")*('Release Calendar'!J5:J504>=TODAY())*('Release Calendar'!J5:J504<=TODAY()+3)*('Release Calendar'!M5:M504<>"Completed")) -> 0
B9: Completion rate | C9: =IF($B$7=0,"",REPT("█",ROUND($G$7/$B$7*48,0))&REPT("░",48-ROUND($G$7/$B$7*48,0))) -> ████████████████████████████████████████░░░░░░░░ | J9: =IF($B$7=0,0,$G$7/$B$7) -> 0.83783784
B11: BY PLATFORM | G11: BY DEPLOYMENT TYPE
B12: DPI | C12: =COUNTIF('Release Calendar'!G5:G504,"DPI") -> 0 | D12: =IF($B$7=0,"",REPT("█",ROUND(C12/$B$7*14,0))) | E12: =IF($B$7=0,0,C12/$B$7) -> 0 | G12: Scheduled | H12: =COUNTIF('Release Calendar'!H5:H504,"Scheduled") -> 32 | I12: =IF($B$7=0,"",REPT("█",ROUND(H12/$B$7*14,0))) -> ████████████ | J12: =IF($B$7=0,0,H12/$B$7) -> 0.86486486
B13: APIs | C13: =COUNTIF('Release Calendar'!G5:G504,"APIs") -> 2 | D13: =IF($B$7=0,"",REPT("█",ROUND(C13/$B$7*14,0))) -> █ | E13: =IF($B$7=0,0,C13/$B$7) -> 0.054054054 | G13: Emergency | H13: =COUNTIF('Release Calendar'!H5:H504,"Emergency") -> 1 | I13: =IF($B$7=0,"",REPT("█",ROUND(H13/$B$7*14,0))) | J13: =IF($B$7=0,0,H13/$B$7) -> 0.027027027
B14: GSM | C14: =COUNTIF('Release Calendar'!G5:G504,"GSM") -> 25 | D14: =IF($B$7=0,"",REPT("█",ROUND(C14/$B$7*14,0))) -> █████████ | E14: =IF($B$7=0,0,C14/$B$7) -> 0.67567568 | G14: Hotfix | H14: =COUNTIF('Release Calendar'!H5:H504,"Hotfix") -> 4 | I14: =IF($B$7=0,"",REPT("█",ROUND(H14/$B$7*14,0))) -> ██ | J14: =IF($B$7=0,0,H14/$B$7) -> 0.10810811
B15: DFS | C15: =COUNTIF('Release Calendar'!G5:G504,"DFS") -> 9 | D15: =IF($B$7=0,"",REPT("█",ROUND(C15/$B$7*14,0))) -> ███ | E15: =IF($B$7=0,0,C15/$B$7) -> 0.24324324
B16: BI | C16: =COUNTIF('Release Calendar'!G5:G504,"BI") -> 0 | D16: =IF($B$7=0,"",REPT("█",ROUND(C16/$B$7*14,0))) | E16: =IF($B$7=0,0,C16/$B$7) -> 0
B18: BY STATUS | G18: BY STAGE
B19: On Track | C19: =COUNTIF('Release Calendar'!M5:M504,"On Track") -> 0 | D19: =IF($B$7=0,"",REPT("█",ROUND(C19/$B$7*14,0))) | E19: =IF($B$7=0,0,C19/$B$7) -> 0 | G19: Development | H19: =COUNTIF('Release Calendar'!K5:K504,"Development") -> 0 | I19: =IF($B$7=0,"",REPT("█",ROUND(H19/$B$7*14,0))) | J19: =IF($B$7=0,0,H19/$B$7) -> 0
B20: At Risk | C20: =COUNTIF('Release Calendar'!M5:M504,"At Risk") -> 0 | D20: =IF($B$7=0,"",REPT("█",ROUND(C20/$B$7*14,0))) | E20: =IF($B$7=0,0,C20/$B$7) -> 0 | G20: SIT | H20: =COUNTIF('Release Calendar'!K5:K504,"SIT") -> 0 | I20: =IF($B$7=0,"",REPT("█",ROUND(H20/$B$7*14,0))) | J20: =IF($B$7=0,0,H20/$B$7) -> 0
B21: Delayed | C21: =COUNTIF('Release Calendar'!M5:M504,"Delayed") -> 0 | D21: =IF($B$7=0,"",REPT("█",ROUND(C21/$B$7*14,0))) | E21: =IF($B$7=0,0,C21/$B$7) -> 0 | G21: UAT | H21: =COUNTIF('Release Calendar'!K5:K504,"UAT") -> 1 | I21: =IF($B$7=0,"",REPT("█",ROUND(H21/$B$7*14,0))) | J21: =IF($B$7=0,0,H21/$B$7) -> 0.027027027
B22: Completed | C22: =COUNTIF('Release Calendar'!M5:M504,"Completed") -> 31 | D22: =IF($B$7=0,"",REPT("█",ROUND(C22/$B$7*14,0))) -> ████████████ | E22: =IF($B$7=0,0,C22/$B$7) -> 0.83783784 | G22: CAB / RFC | H22: =COUNTIF('Release Calendar'!K5:K504,"CAB / RFC") -> 0 | I22: =IF($B$7=0,"",REPT("█",ROUND(H22/$B$7*14,0))) | J22: =IF($B$7=0,0,H22/$B$7) -> 0
B23: On Hold | C23: =COUNTIF('Release Calendar'!M5:M504,"On Hold") -> 2 | D23: =IF($B$7=0,"",REPT("█",ROUND(C23/$B$7*14,0))) -> █ | E23: =IF($B$7=0,0,C23/$B$7) -> 0.054054054 | G23: Code Freeze | H23: =COUNTIF('Release Calendar'!K5:K504,"Code Freeze") -> 0 | I23: =IF($B$7=0,"",REPT("█",ROUND(H23/$B$7*14,0))) | J23: =IF($B$7=0,0,H23/$B$7) -> 0
G24: Pre-Prod | H24: =COUNTIF('Release Calendar'!K5:K504,"Pre-Prod") -> 5 | I24: =IF($B$7=0,"",REPT("█",ROUND(H24/$B$7*14,0))) -> ██ | J24: =IF($B$7=0,0,H24/$B$7) -> 0.13513514
B25: HOLIDAYS | G25: Production | H25: =COUNTIF('Release Calendar'!K5:K504,"Production") -> 28 | I25: =IF($B$7=0,"",REPT("█",ROUND(H25/$B$7*14,0))) -> ███████████ | J25: =IF($B$7=0,0,H25/$B$7) -> 0.75675676
B26: Holiday conflicts | C26: =SUMPRODUCT(('Release Calendar'!Q5:Q504<>"")*(LEFT('Release Calendar'!Q5:Q504,9)="Conflict:")) -> 0 | G26: Completed | H26: =COUNTIF('Release Calendar'!K5:K504,"Completed") -> 3 | I26: =IF($B$7=0,"",REPT("█",ROUND(H26/$B$7*14,0))) -> █ | J26: =IF($B$7=0,0,H26/$B$7) -> 0.081081081
B27: Holidays defined | C27: =COUNTA(Holidays!C5:C34) -> 21 | G27: On Hold | H27: =COUNTIF('Release Calendar'!K5:K504,"On Hold") -> 0 | I27: =IF($B$7=0,"",REPT("█",ROUND(H27/$B$7*14,0))) | J27: =IF($B$7=0,0,H27/$B$7) -> 0
B29: =UPPER(TEXT($L$3,"mmmm yyyy"))&" — MONTHLY VIEW" -> OCTOBER 2026 — MONTHLY VIEW
B30: Releases whose Target Deploy falls in the selected month · change Month / Year below (defaults to the current month)
B31: Month: | C31: =MONTH(TODAY()) -> 10 | D31: Year: | E31: =YEAR(TODAY()) -> 2026 | G31: =TEXT($L$3,"mmmm yyyy") -> October 2026
B32: TOTAL RELEASES | D32: OPEN | G32: COMPLETED | I32: DUE SOON (≤ 3 DAYS)
B33: =SUMPRODUCT(('Release Calendar'!J5:J504<>"")*('Release Calendar'!J5:J504>=$L$3)*('Release Calendar'!J5:J504<=$L$4)) -> 4 | D33: =SUMPRODUCT(('Release Calendar'!J5:J504<>"")*('Release Calendar'!J5:J504>=$L$3)*('Release Calendar'!J5:J504<=$L$4)*('Release Calendar'!B5:B504<>"")*('Release Calendar'!M5:M504<>"Completed")) -> 3 | G33: =SUMPRODUCT(('Release Calendar'!J5:J504<>"")*('Release Calendar'!J5:J504>=$L$3)*('Release Calendar'!J5:J504<=$L$4)*('Release Calendar'!M5:M504="Completed")) -> 1 | I33: =SUMPRODUCT(('Release Calendar'!J5:J504<>"")*('Release Calendar'!J5:J504>=$L$3)*('Release Calendar'!J5:J504<=$L$4)*('Release Calendar'!J5:J504>=TODAY())*('Release Calendar'!J5:J504<=TODAY()+3)*('Release Calendar'!M5:M504<>"Completed")) -> 0
B35: Completion rate | C35: =IF($B$33=0,"",REPT("█",ROUND($G$33/$B$33*48,0))&REPT("░",48-ROUND($G$33/$B$33*48,0))) -> ████████████░░░░░░░░░░░░░░░░░░░░░░░░░░░░░░░░░░░░ | J35: =IF($B$33=0,0,$G$33/$B$33) -> 0.25
B37: BY PLATFORM | G37: BY DEPLOYMENT TYPE
B38: DPI | C38: =SUMPRODUCT(('Release Calendar'!J5:J504<>"")*('Release Calendar'!J5:J504>=$L$3)*('Release Calendar'!J5:J504<=$L$4)*('Release Calendar'!G5:G504="DPI")) -> 0 | D38: =IF($B$33=0,"",REPT("█",ROUND(C38/$B$33*14,0))) | E38: =IF($B$33=0,0,C38/$B$33) -> 0 | G38: Scheduled | H38: =SUMPRODUCT(('Release Calendar'!J5:J504<>"")*('Release Calendar'!J5:J504>=$L$3)*('Release Calendar'!J5:J504<=$L$4)*('Release Calendar'!H5:H504="Scheduled")) -> 3 | I38: =IF($B$33=0,"",REPT("█",ROUND(H38/$B$33*14,0))) -> ███████████ | J38: =IF($B$33=0,0,H38/$B$33) -> 0.75
B39: APIs | C39: =SUMPRODUCT(('Release Calendar'!J5:J504<>"")*('Release Calendar'!J5:J504>=$L$3)*('Release Calendar'!J5:J504<=$L$4)*('Release Calendar'!G5:G504="APIs")) -> 0 | D39: =IF($B$33=0,"",REPT("█",ROUND(C39/$B$33*14,0))) | E39: =IF($B$33=0,0,C39/$B$33) -> 0 | G39: Emergency | H39: =SUMPRODUCT(('Release Calendar'!J5:J504<>"")*('Release Calendar'!J5:J504>=$L$3)*('Release Calendar'!J5:J504<=$L$4)*('Release Calendar'!H5:H504="Emergency")) -> 0 | I39: =IF($B$33=0,"",REPT("█",ROUND(H39/$B$33*14,0))) | J39: =IF($B$33=0,0,H39/$B$33) -> 0
B40: GSM | C40: =SUMPRODUCT(('Release Calendar'!J5:J504<>"")*('Release Calendar'!J5:J504>=$L$3)*('Release Calendar'!J5:J504<=$L$4)*('Release Calendar'!G5:G504="GSM")) -> 2 | D40: =IF($B$33=0,"",REPT("█",ROUND(C40/$B$33*14,0))) -> ███████ | E40: =IF($B$33=0,0,C40/$B$33) -> 0.5 | G40: Hotfix | H40: =SUMPRODUCT(('Release Calendar'!J5:J504<>"")*('Release Calendar'!J5:J504>=$L$3)*('Release Calendar'!J5:J504<=$L$4)*('Release Calendar'!H5:H504="Hotfix")) -> 1 | I40: =IF($B$33=0,"",REPT("█",ROUND(H40/$B$33*14,0))) -> ████ | J40: =IF($B$33=0,0,H40/$B$33) -> 0.25
B41: DFS | C41: =SUMPRODUCT(('Release Calendar'!J5:J504<>"")*('Release Calendar'!J5:J504>=$L$3)*('Release Calendar'!J5:J504<=$L$4)*('Release Calendar'!G5:G504="DFS")) -> 2 | D41: =IF($B$33=0,"",REPT("█",ROUND(C41/$B$33*14,0))) -> ███████ | E41: =IF($B$33=0,0,C41/$B$33) -> 0.5
B42: BI | C42: =SUMPRODUCT(('Release Calendar'!J5:J504<>"")*('Release Calendar'!J5:J504>=$L$3)*('Release Calendar'!J5:J504<=$L$4)*('Release Calendar'!G5:G504="BI")) -> 0 | D42: =IF($B$33=0,"",REPT("█",ROUND(C42/$B$33*14,0))) | E42: =IF($B$33=0,0,C42/$B$33) -> 0
B44: BY STATUS | G44: BY STAGE
B45: On Track | C45: =SUMPRODUCT(('Release Calendar'!J5:J504<>"")*('Release Calendar'!J5:J504>=$L$3)*('Release Calendar'!J5:J504<=$L$4)*('Release Calendar'!M5:M504="On Track")) -> 0 | D45: =IF($B$33=0,"",REPT("█",ROUND(C45/$B$33*14,0))) | E45: =IF($B$33=0,0,C45/$B$33) -> 0 | G45: Development | H45: =SUMPRODUCT(('Release Calendar'!J5:J504<>"")*('Release Calendar'!J5:J504>=$L$3)*('Release Calendar'!J5:J504<=$L$4)*('Release Calendar'!K5:K504="Development")) -> 0 | I45: =IF($B$33=0,"",REPT("█",ROUND(H45/$B$33*14,0))) | J45: =IF($B$33=0,0,H45/$B$33) -> 0
B46: At Risk | C46: =SUMPRODUCT(('Release Calendar'!J5:J504<>"")*('Release Calendar'!J5:J504>=$L$3)*('Release Calendar'!J5:J504<=$L$4)*('Release Calendar'!M5:M504="At Risk")) -> 0 | D46: =IF($B$33=0,"",REPT("█",ROUND(C46/$B$33*14,0))) | E46: =IF($B$33=0,0,C46/$B$33) -> 0 | G46: SIT | H46: =SUMPRODUCT(('Release Calendar'!J5:J504<>"")*('Release Calendar'!J5:J504>=$L$3)*('Release Calendar'!J5:J504<=$L$4)*('Release Calendar'!K5:K504="SIT")) -> 0 | I46: =IF($B$33=0,"",REPT("█",ROUND(H46/$B$33*14,0))) | J46: =IF($B$33=0,0,H46/$B$33) -> 0
B47: Delayed | C47: =SUMPRODUCT(('Release Calendar'!J5:J504<>"")*('Release Calendar'!J5:J504>=$L$3)*('Release Calendar'!J5:J504<=$L$4)*('Release Calendar'!M5:M504="Delayed")) -> 0 | D47: =IF($B$33=0,"",REPT("█",ROUND(C47/$B$33*14,0))) | E47: =IF($B$33=0,0,C47/$B$33) -> 0 | G47: UAT | H47: =SUMPRODUCT(('Release Calendar'!J5:J504<>"")*('Release Calendar'!J5:J504>=$L$3)*('Release Calendar'!J5:J504<=$L$4)*('Release Calendar'!K5:K504="UAT")) -> 0 | I47: =IF($B$33=0,"",REPT("█",ROUND(H47/$B$33*14,0))) | J47: =IF($B$33=0,0,H47/$B$33) -> 0
...

Sheet Holidays
A1: TEKNOSYS · TELECOM DW | Holiday Blackout Calendar
A2: Add holidays here. Target Deploy dates falling on any listed holiday will be blocked automatically.
A3: For a single-day holiday, put the same date in both Start Date and End Date. Multi-day holidays span the whole range inclusive.
A4: # | B4: Holiday Name | C4: Start Date | D4: End Date | E4: Notes | F4: Row Check
A5: 1 | B5: Kashmir Day | C5: 46058 | D5: 46058 | E5: Fixed public holiday | F5: =IF(AND(B5="",C5="",D5="",E5=""),"",IF(AND(B5="",OR(C5<>"",D5<>"")),"Missing name",IF(AND(C5<>"",D5=""),"Missing end date",IF(AND(D5<>"",C5=""),"Missing start date",IF(AND(C5<>"",D5<>"",D5<C5),"End before Start",IF(AND(C5<>"",D5<>"",D5-C5>31),"Range too long (>31d)","OK")))))) -> OK
A6: 2 | B6: Eid-ul-Fitr | C6: 46101 | D6: 46102 | E6: Tentative (moon sighting) | F6: =IF(AND(B6="",C6="",D6="",E6=""),"",IF(AND(B6="",OR(C6<>"",D6<>"")),"Missing name",IF(AND(C6<>"",D6=""),"Missing end date",IF(AND(D6<>"",C6=""),"Missing start date",IF(AND(C6<>"",D6<>"",D6<C6),"End before Start",IF(AND(C6<>"",D6<>"",D6-C6>31),"Range too long (>31d)","OK")))))) -> OK
A7: 3 | B7: Pakistan Day | C7: 46104 | D7: 46104 | E7: Fixed public holiday | F7: =IF(AND(B7="",C7="",D7="",E7=""),"",IF(AND(B7="",OR(C7<>"",D7<>"")),"Missing name",IF(AND(C7<>"",D7=""),"Missing end date",IF(AND(D7<>"",C7=""),"Missing start date",IF(AND(C7<>"",D7<>"",D7<C7),"End before Start",IF(AND(C7<>"",D7<>"",D7-C7>31),"Range too long (>31d)","OK")))))) -> OK
A8: 4 | B8: Labour Day | C8: 46143 | D8: 46143 | E8: Fixed public holiday | F8: =IF(AND(B8="",C8="",D8="",E8=""),"",IF(AND(B8="",OR(C8<>"",D8<>"")),"Missing name",IF(AND(C8<>"",D8=""),"Missing end date",IF(AND(D8<>"",C8=""),"Missing start date",IF(AND(C8<>"",D8<>"",D8<C8),"End before Start",IF(AND(C8<>"",D8<>"",D8-C8>31),"Range too long (>31d)","OK")))))) -> OK
A9: 5 | B9: Eid-ul-Adha | C9: 46169 | D9: 46171 | E9: Tentative (moon sighting) | F9: =IF(AND(B9="",C9="",D9="",E9=""),"",IF(AND(B9="",OR(C9<>"",D9<>"")),"Missing name",IF(AND(C9<>"",D9=""),"Missing end date",IF(AND(D9<>"",C9=""),"Missing start date",IF(AND(C9<>"",D9<>"",D9<C9),"End before Start",IF(AND(C9<>"",D9<>"",D9-C9>31),"Range too long (>31d)","OK")))))) -> OK
A10: 6 | B10: Ashura (9th-10th Muharram) | C10: 46197 | D10: 46198 | E10: Tentative (Islamic calendar) | F10: =IF(AND(B10="",C10="",D10="",E10=""),"",IF(AND(B10="",OR(C10<>"",D10<>"")),"Missing name",IF(AND(C10<>"",D10=""),"Missing end date",IF(AND(D10<>"",C10=""),"Missing start date",IF(AND(C10<>"",D10<>"",D10<C10),"End before Start",IF(AND(C10<>"",D10<>"",D10-C10>31),"Range too long (>31d)","OK")))))) -> OK
A11: 7 | B11: Independence Day | C11: 46248 | D11: 46248 | E11: Fixed public holiday | F11: =IF(AND(B11="",C11="",D11="",E11=""),"",IF(AND(B11="",OR(C11<>"",D11<>"")),"Missing name",IF(AND(C11<>"",D11=""),"Missing end date",IF(AND(D11<>"",C11=""),"Missing start date",IF(AND(C11<>"",D11<>"",D11<C11),"End before Start",IF(AND(C11<>"",D11<>"",D11-C11>31),"Range too long (>31d)","OK")))))) -> OK
A12: 8 | B12: Eid Milad-un-Nabi | C12: 46259 | D12: 46259 | E12: Tentative (moon sighting) | F12: =IF(AND(B12="",C12="",D12="",E12=""),"",IF(AND(B12="",OR(C12<>"",D12<>"")),"Missing name",IF(AND(C12<>"",D12=""),"Missing end date",IF(AND(D12<>"",C12=""),"Missing start date",IF(AND(C12<>"",D12<>"",D12<C12),"End before Start",IF(AND(C12<>"",D12<>"",D12-C12>31),"Range too long (>31d)","OK")))))) -> OK
A13: 9 | B13: Iqbal Day | C13: 46335 | D13: 46335 | E13: Fixed public holiday | F13: =IF(AND(B13="",C13="",D13="",E13=""),"",IF(AND(B13="",OR(C13<>"",D13<>"")),"Missing name",IF(AND(C13<>"",D13=""),"Missing end date",IF(AND(D13<>"",C13=""),"Missing start date",IF(AND(C13<>"",D13<>"",D13<C13),"End before Start",IF(AND(C13<>"",D13<>"",D13-C13>31),"Range too long (>31d)","OK")))))) -> OK
A14: 10 | B14: Quaid-e-Azam Day / Christmas | C14: 46381 | D14: 46381 | E14: Fixed public holiday | F14: =IF(AND(B14="",C14="",D14="",E14=""),"",IF(AND(B14="",OR(C14<>"",D14<>"")),"Missing name",IF(AND(C14<>"",D14=""),"Missing end date",IF(AND(D14<>"",C14=""),"Missing start date",IF(AND(C14<>"",D14<>"",D14<C14),"End before Start",IF(AND(C14<>"",D14<>"",D14-C14>31),"Range too long (>31d)","OK")))))) -> OK
A15: 11 | B15: Kashmir Day | C15: 46423 | D15: 46423 | E15: Fixed public holiday | F15: =IF(AND(B15="",C15="",D15="",E15=""),"",IF(AND(B15="",OR(C15<>"",D15<>"")),"Missing name",IF(AND(C15<>"",D15=""),"Missing end date",IF(AND(D15<>"",C15=""),"Missing start date",IF(AND(C15<>"",D15<>"",D15<C15),"End before Start",IF(AND(C15<>"",D15<>"",D15-C15>31),"Range too long (>31d)","OK")))))) -> OK
A16: 12 | B16: Eid-ul-Fitr | C16: 46456 | D16: 46458 | E16: Tentative (moon sighting) | F16: =IF(AND(B16="",C16="",D16="",E16=""),"",IF(AND(B16="",OR(C16<>"",D16<>"")),"Missing name",IF(AND(C16<>"",D16=""),"Missing end date",IF(AND(D16<>"",C16=""),"Missing start date",IF(AND(C16<>"",D16<>"",D16<C16),"End before Start",IF(AND(C16<>"",D16<>"",D16-C16>31),"Range too long (>31d)","OK")))))) -> OK
... A25: 21 | B25: Quaid-e-Azam Day / Christmas | C25: 46746 | D25: 46746 | E25: Fixed public holiday | F25: =IF(AND(B25="",C25="",D25="",E25=""),"",IF(AND(B25="",OR(C25<>"",D25<>"")),"Missing name",IF(AND(C25<>"",D25=""),"Missing end date",IF(AND(D25<>"",C25=""),"Missing start date",IF(AND(C25<>"",D25<>"",D25<C25),"End before Start",IF(AND(C25<>"",D25<>"",D25-C25>31),"Range too long (>31d)","OK")))))) -> OK
A26: 22 | F26: =IF(AND(B26="",C26="",D26="",E26=""),"",IF(AND(B26="",OR(C26<>"",D26<>"")),"Missing name",IF(AND(C26<>"",D26=""),"Missing end date",IF(AND(D26<>"",C26=""),"Missing start date",IF(AND(C26<>"",D26<>"",D26<C26),"End before Start",IF(AND(C26<>"",D26<>"",D26-C26>31),"Range too long (>31d)","OK"))))))
A27: 23 | F27: =IF(AND(B27="",C27="",D27="",E27=""),"",IF(AND(B27="",OR(C27<>"",D27<>"")),"Missing name",IF(AND(C27<>"",D27=""),"Missing end date",IF(AND(D27<>"",C27=""),"Missing start date",IF(AND(C27<>"",D27<>"",D27<C27),"End before Start",IF(AND(C27<>"",D27<>"",D27-C27>31),"Range too long (>31d)","OK"))))))
A28: 24 | F28: =IF(AND(B28="",C28="",D28="",E28=""),"",IF(AND(B28="",OR(C28<>"",D28<>"")),"Missing name",IF(AND(C28<>"",D28=""),"Missing end date",IF(AND(D28<>"",C28=""),"Missing start date",IF(AND(C28<>"",D28<>"",D28<C28),"End before Start",IF(AND(C28<>"",D28<>"",D28-C28>31),"Range too long (>31d)","OK"))))))
A29: 25 | F29: =IF(AND(B29="",C29="",D29="",E29=""),"",IF(AND(B29="",OR(C29<>"",D29<>"")),"Missing name",IF(AND(C29<>"",D29=""),"Missing end date",IF(AND(D29<>"",C29=""),"Missing start date",IF(AND(C29<>"",D29<>"",D29<C29),"End before Start",IF(AND(C29<>"",D29<>"",D29-C29>31),"Range too long (>31d)","OK"))))))
A30: 26 | F30: =IF(AND(B30="",C30="",D30="",E30=""),"",IF(AND(B30="",OR(C30<>"",D30<>"")),"Missing name",IF(AND(C30<>"",D30=""),"Missing end date",IF(AND(D30<>"",C30=""),"Missing start date",IF(AND(C30<>"",D30<>"",D30<C30),"End before Start",IF(AND(C30<>"",D30<>"",D30-C30>31),"Range too long (>31d)","OK"))))))
A31: 27 | F31: =IF(AND(B31="",C31="",D31="",E31=""),"",IF(AND(B31="",OR(C31<>"",D31<>"")),"Missing name",IF(AND(C31<>"",D31=""),"Missing end date",IF(AND(D31<>"",C31=""),"Missing start date",IF(AND(C31<>"",D31<>"",D31<C31),"End before Start",IF(AND(C31<>"",D31<>"",D31-C31>31),"Range too long (>31d)","OK"))))))
A32: 28 | F32: =IF(AND(B32="",C32="",D32="",E32=""),"",IF(AND(B32="",OR(C32<>"",D32<>"")),"Missing name",IF(AND(C32<>"",D32=""),"Missing end date",IF(AND(D32<>"",C32=""),"Missing start date",IF(AND(C32<>"",D32<>"",D32<C32),"End before Start",IF(AND(C32<>"",D32<>"",D32-C32>31),"Range too long (>31d)","OK"))))))
A33: 29 | F33: =IF(AND(B33="",C33="",D33="",E33=""),"",IF(AND(B33="",OR(C33<>"",D33<>"")),"Missing name",IF(AND(C33<>"",D33=""),"Missing end date",IF(AND(D33<>"",C33=""),"Missing start date",IF(AND(C33<>"",D33<>"",D33<C33),"End before Start",IF(AND(C33<>"",D33<>"",D33-C33>31),"Range too long (>31d)","OK"))))))
A34: 30 | F34: =IF(AND(B34="",C34="",D34="",E34=""),"",IF(AND(B34="",OR(C34<>"",D34<>"")),"Missing name",IF(AND(C34<>"",D34=""),"Missing end date",IF(AND(D34<>"",C34=""),"Missing start date",IF(AND(C34<>"",D34<>"",D34<C34),"End before Start",IF(AND(C34<>"",D34<>"",D34-C34>31),"Range too long (>31d)","OK"))))))

Sheet Release Calendar
A1: TEKNOSYS · TELECOM DW | Release Tracker
A2: Each release is tracked independently · update Current Stage and Status as it moves forward
A3: ✎ Fill in the yellow columns (use the dropdowns for Platform, Type, Stage, Owner and Status; dates as yyyy-mm-dd). ■ The grey-green Holiday Conflict column is automatic — do not edit.
A4: # | B4: Release Name | C4: RITM | D4: CR | E4: Developer Name | F4: Version / Tag | G4: Platform | H4: Deployment Type | I4: Start Date | J4: Target Deploy | K4: Current Stage | L4: Stage Owner | M4: Status | N4: DB Objects Changed | O4: Notes / Blockers | P4: Email | Q4: Holiday Conflict
A5: 1 | B5: BVS Sales Old Age flag Core | E5: Rabia Qayyum | F5: v1 | G5: GSM | H5: Scheduled | I5: 46238 | J5: 46246 | K5: Production | L5: Ops Team | M5: Completed | O5: Nothing | Q5: =IF(OR(B5="",J5=""),"",IF(SUMPRODUCT((J5>=HolidayStart)*(J5<=HolidayEnd)*(HolidayStart<>""))>0,"Conflict: "&INDEX(HolidayName,SUMPRODUCT((J5>=HolidayStart)*(J5<=HolidayEnd)*(HolidayStart<>"")*ROW(HolidayStart))-ROW(INDEX(HolidayStart,1,1))+1),""))
A6: 2 | B6: OMNI API table export | E6: Mahum Tariq | F6: V1 | G6: APIs | H6: Scheduled | I6: 46244 | J6: 46246 | K6: Production | L6: Dev Team | M6: Completed | O6: NA | Q6: =IF(OR(B6="",J6=""),"",IF(SUMPRODUCT((J6>=HolidayStart)*(J6<=HolidayEnd)*(HolidayStart<>""))>0,"Conflict: "&INDEX(HolidayName,SUMPRODUCT((J6>=HolidayStart)*(J6<=HolidayEnd)*(HolidayStart<>"")*ROW(HolidayStart))-ROW(INDEX(HolidayStart,1,1))+1),""))
A7: 3 | B7: Multiplay 90 Days (Pre and Post) | E7: Ukasha Shafique | F7: V1 | G7: GSM | H7: Scheduled | I7: 46237 | J7: 46252 | K7: Production | L7: Dev Team | M7: Completed | O7: None | Q7: =IF(OR(B7="",J7=""),"",IF(SUMPRODUCT((J7>=HolidayStart)*(J7<=HolidayEnd)*(HolidayStart<>""))>0,"Conflict: "&INDEX(HolidayName,SUMPRODUCT((J7>=HolidayStart)*(J7<=HolidayEnd)*(HolidayStart<>"")*ROW(HolidayStart))-ROW(INDEX(HolidayStart,1,1))+1),""))
A8: 4 | B8: Addition in Universal Charging Base | E8: Hafsa Malik | F8: V1 | G8: GSM | H8: Scheduled | I8: 46251 | J8: 46253 | K8: Production | L8: Dev Lead | M8: Completed | O8: None | Q8: =IF(OR(B8="",J8=""),"",IF(SUMPRODUCT((J8>=HolidayStart)*(J8<=HolidayEnd)*(HolidayStart<>""))>0,"Conflict: "&INDEX(HolidayName,SUMPRODUCT((J8>=HolidayStart)*(J8<=HolidayEnd)*(HolidayStart<>"")*ROW(HolidayStart))-ROW(INDEX(HolidayStart,1,1))+1),""))
A9: 5 | B9: postpaid lifecycle hotfix | E9: Moeiz Bhatti | F9: V1 | G9: GSM | H9: Hotfix | I9: 46251 | J9: 46251 | K9: Production | L9: Dev Team | M9: Completed | O9: NONE | Q9: =IF(OR(B9="",J9=""),"",IF(SUMPRODUCT((J9>=HolidayStart)*(J9<=HolidayEnd)*(HolidayStart<>""))>0,"Conflict: "&INDEX(HolidayName,SUMPRODUCT((J9>=HolidayStart)*(J9<=HolidayEnd)*(HolidayStart<>"")*ROW(HolidayStart))-ROW(INDEX(HolidayStart,1,1))+1),""))
A10: 6 | B10: BVS Sales Old Age flag Semantic | E10: Rabia Qayyum | F10: V2 | G10: GSM | H10: Scheduled | I10: 46246 | J10: 46253 | K10: Production | L10: Dev Team | M10: Completed | O10: None | Q10: =IF(OR(B10="",J10=""),"",IF(SUMPRODUCT((J10>=HolidayStart)*(J10<=HolidayEnd)*(HolidayStart<>""))>0,"Conflict: "&INDEX(HolidayName,SUMPRODUCT((J10>=HolidayStart)*(J10<=HolidayEnd)*(HolidayStart<>"")*ROW(HolidayStart))-ROW(INDEX(HolidayStart,1,1))+1),""))
A11: 7 | B11: UCIP_LKP update | E11: Daniyal Ahmed | F11: V1 | G11: GSM | H11: Scheduled | I11: 46252 | J11: 46253 | K11: Production | L11: Ops Team | M11: Completed | O11: None | Q11: =IF(OR(B11="",J11=""),"",IF(SUMPRODUCT((J11>=HolidayStart)*(J11<=HolidayEnd)*(HolidayStart<>""))>0,"Conflict: "&INDEX(HolidayName,SUMPRODUCT((J11>=HolidayStart)*(J11<=HolidayEnd)*(HolidayStart<>"")*ROW(HolidayStart))-ROW(INDEX(HolidayStart,1,1))+1),""))
A12: 8 | B12: Daily Kpi Report - Addition of KPIs | E12: Afia Abdul Rehman | F12: V3 | G12: DFS | H12: Scheduled | I12: 46267 | J12: 46267 | K12: Production | L12: Ops Team | M12: Completed | O12: None | Q12: =IF(OR(B12="",J12=""),"",IF(SUMPRODUCT((J12>=HolidayStart)*(J12<=HolidayEnd)*(HolidayStart<>""))>0,"Conflict: "&INDEX(HolidayName,SUMPRODUCT((J12>=HolidayStart)*(J12<=HolidayEnd)*(HolidayStart<>"")*ROW(HolidayStart))-ROW(INDEX(HolidayStart,1,1))+1),""))
A13: 9 | B13: Reward Hub Ceo Category | E13: Abdul Wahab Malik | F13: V1 | G13: DFS | H13: Emergency | I13: 46266 | J13: 46269 | K13: Production | L13: Release Manager | M13: Completed | O13: None | Q13: =IF(OR(B13="",J13=""),"",IF(SUMPRODUCT((J13>=HolidayStart)*(J13<=HolidayEnd)*(HolidayStart<>""))>0,"Conflict: "&INDEX(HolidayName,SUMPRODUCT((J13>=HolidayStart)*(J13<=HolidayEnd)*(HolidayStart<>"")*ROW(HolidayStart))-ROW(INDEX(HolidayStart,1,1))+1),""))
A14: 10 | B14: Daily KPI Report- Addition of App Kpis | E14: Afia Abdul Rehman | F14: V10 | G14: DFS | H14: Scheduled | I14: 46274 | J14: 46274 | K14: Completed | L14: Release Manager | M14: Completed | O14: None | Q14: =IF(OR(B14="",J14=""),"",IF(SUMPRODUCT((J14>=HolidayStart)*(J14<=HolidayEnd)*(HolidayStart<>""))>0,"Conflict: "&INDEX(HolidayName,SUMPRODUCT((J14>=HolidayStart)*(J14<=HolidayEnd)*(HolidayStart<>"")*ROW(HolidayStart))-ROW(INDEX(HolidayStart,1,1))+1),""))
A15: 11 | B15: Postpaid lifecycle DDLS fix | E15: Moeiz Ali Bhatti | F15: v1 | G15: GSM | H15: Scheduled | I15: 46274 | J15: 46274 | K15: Production | L15: Release Manager | M15: Completed | O15: None | Q15: =IF(OR(B15="",J15=""),"",IF(SUMPRODUCT((J15>=HolidayStart)*(J15<=HolidayEnd)*(HolidayStart<>""))>0,"Conflict: "&INDEX(HolidayName,SUMPRODUCT((J15>=HolidayStart)*(J15<=HolidayEnd)*(HolidayStart<>"")*ROW(HolidayStart))-ROW(INDEX(HolidayStart,1,1))+1),""))
A16: 12 | B16: Jazz Advance TPT Update | E16: Hafsa Malik | F16: V1 | G16: APIs | H16: Scheduled | I16: 46265 | J16: 46265 | K16: Completed | L16: Ops Team | M16: Completed | O16: None | Q16: =IF(OR(B16="",J16=""),"",IF(SUMPRODUCT((J16>=HolidayStart)*(J16<=HolidayEnd)*(HolidayStart<>""))>0,"Conflict: "&INDEX(HolidayName,SUMPRODUCT((J16>=HolidayStart)*(J16<=HolidayEnd)*(HolidayStart<>"")*ROW(HolidayStart))-ROW(INDEX(HolidayStart,1,1))+1),""))
... A18: 14 | B18: Simosa Parent Child Sourcing | E18: Daniyal Ahmed | F18: V1 | G18: GSM | H18: Scheduled | I18: 46273 | J18: 46274 | K18: Production | L18: Dev Team | M18: Completed | O18: None | Q18: =IF(OR(B18="",J18=""),"",IF(SUMPRODUCT((J18>=HolidayStart)*(J18<=HolidayEnd)*(HolidayStart<>""))>0,"Conflict: "&INDEX(HolidayName,SUMPRODUCT((J18>=HolidayStart)*(J18<=HolidayEnd)*(HolidayStart<>"")*ROW(HolidayStart))-ROW(INDEX(HolidayStart,1,1))+1),""))
A19: 15 | B19: live app hierarchy fix | E19: Asfandyar Barki | F19: v1 | G19: GSM | H19: Hotfix | I19: 46243 | J19: 46243 | K19: Production | L19: Dev Team | M19: Completed | Q19: =IF(OR(B19="",J19=""),"",IF(SUMPRODUCT((J19>=HolidayStart)*(J19<=HolidayEnd)*(HolidayStart<>""))>0,"Conflict: "&INDEX(HolidayName,SUMPRODUCT((J19>=HolidayStart)*(J19<=HolidayEnd)*(HolidayStart<>"")*ROW(HolidayStart))-ROW(INDEX(HolidayStart,1,1))+1),""))
A20: 16 | B20: Dekho - Digital Lifecycle Snapshot Discontinuation | E20: Ahmad Faizan | F20: v1 | G20: GSM | H20: Scheduled | I20: 46273 | J20: 46274 | K20: Production | L20: Dev Team | M20: Completed | O20: None | Q20: =IF(OR(B20="",J20=""),"",IF(SUMPRODUCT((J20>=HolidayStart)*(J20<=HolidayEnd)*(HolidayStart<>""))>0,"Conflict: "&INDEX(HolidayName,SUMPRODUCT((J20>=HolidayStart)*(J20<=HolidayEnd)*(HolidayStart<>"")*ROW(HolidayStart))-ROW(INDEX(HolidayStart,1,1))+1),""))
A21: 17 | B21: DFS Lifecycle new columns addition | E21: Muhammad Fawad Akhtar | F21: v4 | G21: DFS | H21: Scheduled | I21: 46281 | J21: 46281 | K21: Production | L21: Dev Team | M21: Completed | Q21: =IF(OR(B21="",J21=""),"",IF(SUMPRODUCT((J21>=HolidayStart)*(J21<=HolidayEnd)*(HolidayStart<>""))>0,"Conflict: "&INDEX(HolidayName,SUMPRODUCT((J21>=HolidayStart)*(J21<=HolidayEnd)*(HolidayStart<>"")*ROW(HolidayStart))-ROW(INDEX(HolidayStart,1,1))+1),""))
A22: 18 | B22: lifecycle view fix for sbskey | E22: Moeiz Bhatti | F22: v1 | G22: GSM | H22: Scheduled | I22: 46281 | J22: 46281 | K22: Production | L22: Dev Team | M22: Completed | P22: sbscrpn_key tagging fix in 3 views of new lifecycle. | Q22: =IF(OR(B22="",J22=""),"",IF(SUMPRODUCT((J22>=HolidayStart)*(J22<=HolidayEnd)*(HolidayStart<>""))>0,"Conflict: "&INDEX(HolidayName,SUMPRODUCT((J22>=HolidayStart)*(J22<=HolidayEnd)*(HolidayStart<>"")*ROW(HolidayStart))-ROW(INDEX(HolidayStart,1,1))+1),""))
A23: 19 | B23: SDS 5G Attributes Addition | E23: Bilal Siddiqui | F23: v1 | G23: GSM | H23: Scheduled | I23: 46281 | J23: 46281 | K23: Production | L23: Ops Team | M23: Completed | Q23: =IF(OR(B23="",J23=""),"",IF(SUMPRODUCT((J23>=HolidayStart)*(J23<=HolidayEnd)*(HolidayStart<>""))>0,"Conflict: "&INDEX(HolidayName,SUMPRODUCT((J23>=HolidayStart)*(J23<=HolidayEnd)*(HolidayStart<>"")*ROW(HolidayStart))-ROW(INDEX(HolidayStart,1,1))+1),""))
A24: 20 | B24: Rox Achievement Fix | E24: Asfandyar Barki | F24: v1 | G24: GSM | H24: Hotfix | I24: 46286 | J24: 46286 | K24: Production | L24: Dev Team | M24: Completed | P24: Re: Difference in Postpaid and ROX achievements in Datewise and in indivivdual reports | RM-1990 | Q24: =IF(OR(B24="",J24=""),"",IF(SUMPRODUCT((J24>=HolidayStart)*(J24<=HolidayEnd)*(HolidayStart<>""))>0,"Conflict: "&INDEX(HolidayName,SUMPRODUCT((J24>=HolidayStart)*(J24<=HolidayEnd)*(HolidayStart<>"")*ROW(HolidayStart))-ROW(INDEX(HolidayStart,1,1))+1),""))
A25: 21 | B25: CPS License Log & Daily OFT Report | E25: Waqar Saeed | F25: v1 | G25: DFS | H25: Scheduled | I25: 46275 | J25: 46287 | K25: UAT | L25: Dev Team | M25: Completed | Q25: =IF(OR(B25="",J25=""),"",IF(SUMPRODUCT((J25>=HolidayStart)*(J25<=HolidayEnd)*(HolidayStart<>""))>0,"Conflict: "&INDEX(HolidayName,SUMPRODUCT((J25>=HolidayStart)*(J25<=HolidayEnd)*(HolidayStart<>"")*ROW(HolidayStart))-ROW(INDEX(HolidayStart,1,1))+1),""))
A26: 22 | B26: NBO Lookup - New Sourcing | E26: Asfandyar Barki | F26: v1 | G26: GSM | H26: Scheduled | I26: 46288 | J26: 46288 | K26: Production | L26: Dev Team | M26: Completed | Q26: =IF(OR(B26="",J26=""),"",IF(SUMPRODUCT((J26>=HolidayStart)*(J26<=HolidayEnd)*(HolidayStart<>""))>0,"Conflict: "&INDEX(HolidayName,SUMPRODUCT((J26>=HolidayStart)*(J26<=HolidayEnd)*(HolidayStart<>"")*ROW(HolidayStart))-ROW(INDEX(HolidayStart,1,1))+1),""))
A27: 23 | B27: Sales Fact 5G Date Addition | E27: Bilal Siddiqui | F27: v1 | G27: GSM | H27: Scheduled | I27: 46290 | J27: 46295 | K27: Production | L27: Dev Team | M27: Completed | Q27: =IF(OR(B27="",J27=""),"",IF(SUMPRODUCT((J27>=HolidayStart)*(J27<=HolidayEnd)*(HolidayStart<>""))>0,"Conflict: "&INDEX(HolidayName,SUMPRODUCT((J27>=HolidayStart)*(J27<=HolidayEnd)*(HolidayStart<>"")*ROW(HolidayStart))-ROW(INDEX(HolidayStart,1,1))+1),""))
A28: 24 | B28: postpaid live | E28: moeiz bhatti | F28: v1 | G28: GSM | H28: Scheduled | I28: 46295 | J28: 46295 | K28: Production | L28: Dev Team | M28: Completed | Q28: =IF(OR(B28="",J28=""),"",IF(SUMPRODUCT((J28>=HolidayStart)*(J28<=HolidayEnd)*(HolidayStart<>""))>0,"Conflict: "&INDEX(HolidayName,SUMPRODUCT((J28>=HolidayStart)*(J28<=HolidayEnd)*(HolidayStart<>"")*ROW(HolidayStart))-ROW(INDEX(HolidayStart,1,1))+1),""))
A29: 25 | B29: addition of KPIS in script dashboard day wise kpi | E29: Fawad Akhtar | F29: v2 | G29: DFS | H29: Scheduled | I29: 46295 | J29: 46295 | K29: Production | L29: Ops Team | M29: Completed | Q29: =IF(OR(B29="",J29=""),"",IF(SUMPRODUCT((J29>=HolidayStart)*(J29<=HolidayEnd)*(HolidayStart<>""))>0,"Conflict: "&INDEX(HolidayName,SUMPRODUCT((J29>=HolidayStart)*(J29<=HolidayEnd)*(HolidayStart<>"")*ROW(HolidayStart))-ROW(INDEX(HolidayStart,1,1))+1),""))
A30: 26 | B30: Postpaid Conversion API | E30: Hafsa Malik | F30: v1 | G30: GSM | H30: Scheduled | I30: 46293 | J30: 46295 | K30: Pre-Prod | L30: Dev Team | M30: Completed | Q30: =IF(OR(B30="",J30=""),"",IF(SUMPRODUCT((J30>=HolidayStart)*(J30<=HolidayEnd)*(HolidayStart<>""))>0,"Conflict: "&INDEX(HolidayName,SUMPRODUCT((J30>=HolidayStart)*(J30<=HolidayEnd)*(HolidayStart<>"")*ROW(HolidayStart))-ROW(INDEX(HolidayStart,1,1))+1),""))
A31: 27 | B31: Jazz Advance TPT Update | E31: Hafsa Malik | F31: V1 | G31: GSM | H31: Scheduled | I31: 46293 | J31: 46295 | K31: Pre-Prod | L31: Dev Team | M31: Completed | Q31: =IF(OR(B31="",J31=""),"",IF(SUMPRODUCT((J31>=HolidayStart)*(J31<=HolidayEnd)*(HolidayStart<>""))>0,"Conflict: "&INDEX(HolidayName,SUMPRODUCT((J31>=HolidayStart)*(J31<=HolidayEnd)*(HolidayStart<>"")*ROW(HolidayStart))-ROW(INDEX(HolidayStart,1,1))+1),""))
A32: 28 | B32: Jazz CX IVR API | E32: Husinah Amir | F32: V1 | G32: GSM | H32: Scheduled | I32: 46293 | J32: 46295 | K32: Production | L32: Dev Team | M32: On Hold | Q32: =IF(OR(B32="",J32=""),"",IF(SUMPRODUCT((J32>=HolidayStart)*(J32<=HolidayEnd)*(HolidayStart<>""))>0,"Conflict: "&INDEX(HolidayName,SUMPRODUCT((J32>=HolidayStart)*(J32<=HolidayEnd)*(HolidayStart<>"")*ROW(HolidayStart))-ROW(INDEX(HolidayStart,1,1))+1),""))
A33: 29 | B33: FikrFree New Sourcing | E33: Ahmad Faizan | F33: V1 | G33: JLV | H33: Scheduled | I33: 46294 | J33: 46295 | K33: Production | L33: Dev Team | M33: On Hold | Q33: =IF(OR(B33="",J33=""),"",IF(SUMPRODUCT((J33>=HolidayStart)*(J33<=HolidayEnd)*(HolidayStart<>""))>0,"Conflict: "&INDEX(HolidayName,SUMPRODUCT((J33>=HolidayStart)*(J33<=HolidayEnd)*(HolidayStart<>"")*ROW(HolidayStart))-ROW(INDEX(HolidayStart,1,1))+1),""))
A34: 30 | B34: MSPH COLUMN ADDITION | E34: Tauseef haq | F34: V1 | G34: GSM | H34: Scheduled | I34: 46295 | J34: 46295 | K34: Production | L34: Dev Team | M34: Completed | Q34: =IF(OR(B34="",J34=""),"",IF(SUMPRODUCT((J34>=HolidayStart)*(J34<=HolidayEnd)*(HolidayStart<>""))>0,"Conflict: "&INDEX(HolidayName,SUMPRODUCT((J34>=HolidayStart)*(J34<=HolidayEnd)*(HolidayStart<>"")*ROW(HolidayStart))-ROW(INDEX(HolidayStart,1,1))+1),""))
A35: 31 | B35: UCIP_LKP update (Gamenow Ucips) | E35: Daniyal Ahmed | F35: V1 | G35: GSM | H35: Scheduled | I35: 46295 | J35: 46295 | K35: Pre-Prod | L35: Dev Team | M35: Completed | Q35: =IF(OR(B35="",J35=""),"",IF(SUMPRODUCT((J35>=HolidayStart)*(J35<=HolidayEnd)*(HolidayStart<>""))>0,"Conflict: "&INDEX(HolidayName,SUMPRODUCT((J35>=HolidayStart)*(J35<=HolidayEnd)*(HolidayStart<>"")*ROW(HolidayStart))-ROW(INDEX(HolidayStart,1,1))+1),""))
A36: 32 | B36: 699 ODS – Subscriber Upgrade/Whitelisting Plan | E36: Asfandyar Barki | F36: v1 | G36: GSM | H36: Scheduled | I36: 46295 | J36: 46295 | K36: Production | L36: Dev Team | M36: Completed | Q36: =IF(OR(B36="",J36=""),"",IF(SUMPRODUCT((J36>=HolidayStart)*(J36<=HolidayEnd)*(HolidayStart<>""))>0,"Conflict: "&INDEX(HolidayName,SUMPRODUCT((J36>=HolidayStart)*(J36<=HolidayEnd)*(HolidayStart<>"")*ROW(HolidayStart))-ROW(INDEX(HolidayStart,1,1))+1),""))
A37: 33 | B37: Tamasha IP list update | E37: Ahmad Faizan | F37: V1 | G37: GSM | H37: Scheduled | I37: 46302 | J37: 46302 | K37: Pre-Prod | L37: Dev Team | Q37: =IF(OR(B37="",J37=""),"",IF(SUMPRODUCT((J37>=HolidayStart)*(J37<=HolidayEnd)*(HolidayStart<>""))>0,"Conflict: "&INDEX(HolidayName,SUMPRODUCT((J37>=HolidayStart)*(J37<=HolidayEnd)*(HolidayStart<>"")*ROW(HolidayStart))-ROW(INDEX(HolidayStart,1,1))+1),""))
A38: 34 | B38: Reward Hub Ceo Category | E38: Afia Abdul Rehman | F38: V1 | G38: DFS | H38: Scheduled | I38: 46302 | J38: 46302 | K38: Production | M38: Completed | Q38: =IF(OR(B38="",J38=""),"",IF(SUMPRODUCT((J38>=HolidayStart)*(J38<=HolidayEnd)*(HolidayStart<>""))>0,"Conflict: "&INDEX(HolidayName,SUMPRODUCT((J38>=HolidayStart)*(J38<=HolidayEnd)*(HolidayStart<>"")*ROW(HolidayStart))-ROW(INDEX(HolidayStart,1,1))+1),""))
A39: 35 | B39: Digital Funnel Daily and linked MP Marts - Tamasha Definition Update | E39: Daniyal Ahmed | G39: GSM | H39: Scheduled | I39: 46302 | K39: Pre-Prod | L39: Dev Team | Q39: =IF(OR(B39="",J39=""),"",IF(SUMPRODUCT((J39>=HolidayStart)*(J39<=HolidayEnd)*(HolidayStart<>""))>0,"Conflict: "&INDEX(HolidayName,SUMPRODUCT((J39>=HolidayStart)*(J39<=HolidayEnd)*(HolidayStart<>"")*ROW(HolidayStart))-ROW(INDEX(HolidayStart,1,1))+1),""))
A40: 36 | B40: DFS Lifecycle new columns addition | E40: Fawad Akhtar | F40: v4 | G40: DFS | H40: Scheduled | I40: 46307 | J40: 46307 | K40: Production | Q40: =IF(OR(B40="",J40=""),"",IF(SUMPRODUCT((J40>=HolidayStart)*(J40<=HolidayEnd)*(HolidayStart<>""))>0,"Conflict: "&INDEX(HolidayName,SUMPRODUCT((J40>=HolidayStart)*(J40<=HolidayEnd)*(HolidayStart<>"")*ROW(HolidayStart))-ROW(INDEX(HolidayStart,1,1))+1),""))
A41: 37 | B41: b2c sales hotfix | E41: Moeiz Bhatti | F41: v1 | G41: GSM | H41: Hotfix | I41: 46308 | J41: 46308 | K41: Production | L41: Dev Team | Q41: =IF(OR(B41="",J41=""),"",IF(SUMPRODUCT((J41>=HolidayStart)*(J41<=HolidayEnd)*(HolidayStart<>""))>0,"Conflict: "&INDEX(HolidayName,SUMPRODUCT((J41>=HolidayStart)*(J41<=HolidayEnd)*(HolidayStart<>"")*ROW(HolidayStart))-ROW(INDEX(HolidayStart,1,1))+1),""))
...

Sheet Calendar View
A1: TEKNOSYS · TELECOM DW | Release Timeline 2026
A2: Gantt bars run from Start Date to Target Deploy on the Release Calendar sheet · coloured by Status · highlighted column = current month
B3: Status key ▸ | E3: On Track | G3: At Risk | I3: Delayed | K3: Completed | M3: On Hold | O3: ★ this month
A4: # | B4: Release Name | C4: Current Stage | D4: Status | E4: Jan 2026 | F4: Feb 2026 | G4: Mar 2026 | H4: Apr 2026 | I4: May 2026 | J4: Jun 2026 | K4: Jul 2026 | L4: Aug 2026 | M4: Sep 2026 | N4: Oct 2026 | O4: Nov 2026 | P4: Dec 2026
A5: 1 | B5: =IF('Release Calendar'!B5<>"",'Release Calendar'!B5,"") -> BVS Sales Old Age flag Core | C5: =IF('Release Calendar'!K5<>"",'Release Calendar'!K5,"") -> Production | D5: =IF('Release Calendar'!M5<>"",'Release Calendar'!M5,"") -> Completed | E5: =IF(AND(Q5<>"",R5<>"",DATE(2026,2,0)>=Q5,DATE(2026,1,1)<=R5),"█","") | F5: =IF(AND(Q5<>"",R5<>"",DATE(2026,3,0)>=Q5,DATE(2026,2,1)<=R5),"█","") | G5: =IF(AND(Q5<>"",R5<>"",DATE(2026,4,0)>=Q5,DATE(2026,3,1)<=R5),"█","") | H5: =IF(AND(Q5<>"",R5<>"",DATE(2026,5,0)>=Q5,DATE(2026,4,1)<=R5),"█","") | I5: =IF(AND(Q5<>"",R5<>"",DATE(2026,6,0)>=Q5,DATE(2026,5,1)<=R5),"█","") | J5: =IF(AND(Q5<>"",R5<>"",DATE(2026,7,0)>=Q5,DATE(2026,6,1)<=R5),"█","") | K5: =IF(AND(Q5<>"",R5<>"",DATE(2026,8,0)>=Q5,DATE(2026,7,1)<=R5),"█","") | L5: =IF(AND(Q5<>"",R5<>"",DATE(2026,9,0)>=Q5,DATE(2026,8,1)<=R5),"█","") -> █ | M5: =IF(AND(Q5<>"",R5<>"",DATE(2026,10,0)>=Q5,DATE(2026,9,1)<=R5),"█","") | N5: =IF(AND(Q5<>"",R5<>"",DATE(2026,11,0)>=Q5,DATE(2026,10,1)<=R5),"█","") | O5: =IF(AND(Q5<>"",R5<>"",DATE(2026,12,0)>=Q5,DATE(2026,11,1)<=R5),"█","") | P5: =IF(AND(Q5<>"",R5<>"",DATE(2026,12,31)>=Q5,DATE(2026,12,1)<=R5),"█","") | Q5: =IF('Release Calendar'!I5<>"",'Release Calendar'!I5,"") -> 46238 | R5: =IF('Release Calendar'!J5<>"",'Release Calendar'!J5,"") -> 46246
A6: 2 | B6: =IF('Release Calendar'!B6<>"",'Release Calendar'!B6,"") -> OMNI API table export | C6: =IF('Release Calendar'!K6<>"",'Release Calendar'!K6,"") -> Production | D6: =IF('Release Calendar'!M6<>"",'Release Calendar'!M6,"") -> Completed | E6: =IF(AND(Q6<>"",R6<>"",DATE(2026,2,0)>=Q6,DATE(2026,1,1)<=R6),"█","") | F6: =IF(AND(Q6<>"",R6<>"",DATE(2026,3,0)>=Q6,DATE(2026,2,1)<=R6),"█","") | G6: =IF(AND(Q6<>"",R6<>"",DATE(2026,4,0)>=Q6,DATE(2026,3,1)<=R6),"█","") | H6: =IF(AND(Q6<>"",R6<>"",DATE(2026,5,0)>=Q6,DATE(2026,4,1)<=R6),"█","") | I6: =IF(AND(Q6<>"",R6<>"",DATE(2026,6,0)>=Q6,DATE(2026,5,1)<=R6),"█","") | J6: =IF(AND(Q6<>"",R6<>"",DATE(2026,7,0)>=Q6,DATE(2026,6,1)<=R6),"█","") | K6: =IF(AND(Q6<>"",R6<>"",DATE(2026,8,0)>=Q6,DATE(2026,7,1)<=R6),"█","") | L6: =IF(AND(Q6<>"",R6<>"",DATE(2026,9,0)>=Q6,DATE(2026,8,1)<=R6),"█","") -> █ | M6: =IF(AND(Q6<>"",R6<>"",DATE(2026,10,0)>=Q6,DATE(2026,9,1)<=R6),"█","") | N6: =IF(AND(Q6<>"",R6<>"",DATE(2026,11,0)>=Q6,DATE(2026,10,1)<=R6),"█","") | O6: =IF(AND(Q6<>"",R6<>"",DATE(2026,12,0)>=Q6,DATE(2026,11,1)<=R6),"█","") | P6: =IF(AND(Q6<>"",R6<>"",DATE(2026,12,31)>=Q6,DATE(2026,12,1)<=R6),"█","") | Q6: =IF('Release Calendar'!I6<>"",'Release Calendar'!I6,"") -> 46244 | R6: =IF('Release Calendar'!J6<>"",'Release Calendar'!J6,"") -> 46246
A7: 3 | B7: =IF('Release Calendar'!B7<>"",'Release Calendar'!B7,"") -> Multiplay 90 Days (Pre and Post) | C7: =IF('Release Calendar'!K7<>"",'Release Calendar'!K7,"") -> Production | D7: =IF('Release Calendar'!M7<>"",'Release Calendar'!M7,"") -> Completed | E7: =IF(AND(Q7<>"",R7<>"",DATE(2026,2,0)>=Q7,DATE(2026,1,1)<=R7),"█","") | F7: =IF(AND(Q7<>"",R7<>"",DATE(2026,3,0)>=Q7,DATE(2026,2,1)<=R7),"█","") | G7: =IF(AND(Q7<>"",R7<>"",DATE(2026,4,0)>=Q7,DATE(2026,3,1)<=R7),"█","") | H7: =IF(AND(Q7<>"",R7<>"",DATE(2026,5,0)>=Q7,DATE(2026,4,1)<=R7),"█","") | I7: =IF(AND(Q7<>"",R7<>"",DATE(2026,6,0)>=Q7,DATE(2026,5,1)<=R7),"█","") | J7: =IF(AND(Q7<>"",R7<>"",DATE(2026,7,0)>=Q7,DATE(2026,6,1)<=R7),"█","") | K7: =IF(AND(Q7<>"",R7<>"",DATE(2026,8,0)>=Q7,DATE(2026,7,1)<=R7),"█","") | L7: =IF(AND(Q7<>"",R7<>"",DATE(2026,9,0)>=Q7,DATE(2026,8,1)<=R7),"█","") -> █ | M7: =IF(AND(Q7<>"",R7<>"",DATE(2026,10,0)>=Q7,DATE(2026,9,1)<=R7),"█","") | N7: =IF(AND(Q7<>"",R7<>"",DATE(2026,11,0)>=Q7,DATE(2026,10,1)<=R7),"█","") | O7: =IF(AND(Q7<>"",R7<>"",DATE(2026,12,0)>=Q7,DATE(2026,11,1)<=R7),"█","") | P7: =IF(AND(Q7<>"",R7<>"",DATE(2026,12,31)>=Q7,DATE(2026,12,1)<=R7),"█","") | Q7: =IF('Release Calendar'!I7<>"",'Release Calendar'!I7,"") -> 46237 | R7: =IF('Release Calendar'!J7<>"",'Release Calendar'!J7,"") -> 46252
A8: 4 | B8: =IF('Release Calendar'!B8<>"",'Release Calendar'!B8,"") -> Addition in Universal Charging Base | C8: =IF('Release Calendar'!K8<>"",'Release Calendar'!K8,"") -> Production | D8: =IF('Release Calendar'!M8<>"",'Release Calendar'!M8,"") -> Completed | E8: =IF(AND(Q8<>"",R8<>"",DATE(2026,2,0)>=Q8,DATE(2026,1,1)<=R8),"█","") | F8: =IF(AND(Q8<>"",R8<>"",DATE(2026,3,0)>=Q8,DATE(2026,2,1)<=R8),"█","") | G8: =IF(AND(Q8<>"",R8<>"",DATE(2026,4,0)>=Q8,DATE(2026,3,1)<=R8),"█","") | H8: =IF(AND(Q8<>"",R8<>"",DATE(2026,5,0)>=Q8,DATE(2026,4,1)<=R8),"█","") | I8: =IF(AND(Q8<>"",R8<>"",DATE(2026,6,0)>=Q8,DATE(2026,5,1)<=R8),"█","") | J8: =IF(AND(Q8<>"",R8<>"",DATE(2026,7,0)>=Q8,DATE(2026,6,1)<=R8),"█","") | K8: =IF(AND(Q8<>"",R8<>"",DATE(2026,8,0)>=Q8,DATE(2026,7,1)<=R8),"█","") | L8: =IF(AND(Q8<>"",R8<>"",DATE(2026,9,0)>=Q8,DATE(2026,8,1)<=R8),"█","") -> █ | M8: =IF(AND(Q8<>"",R8<>"",DATE(2026,10,0)>=Q8,DATE(2026,9,1)<=R8),"█","") | N8: =IF(AND(Q8<>"",R8<>"",DATE(2026,11,0)>=Q8,DATE(2026,10,1)<=R8),"█","") | O8: =IF(AND(Q8<>"",R8<>"",DATE(2026,12,0)>=Q8,DATE(2026,11,1)<=R8),"█","") | P8: =IF(AND(Q8<>"",R8<>"",DATE(2026,12,31)>=Q8,DATE(2026,12,1)<=R8),"█","") | Q8: =IF('Release Calendar'!I8<>"",'Release Calendar'!I8,"") -> 46251 | R8: =IF('Release Calendar'!J8<>"",'Release Calendar'!J8,"") -> 46253
A9: 5 | B9: =IF('Release Calendar'!B9<>"",'Release Calendar'!B9,"") -> postpaid lifecycle hotfix | C9: =IF('Release Calendar'!K9<>"",'Release Calendar'!K9,"") -> Production | D9: =IF('Release Calendar'!M9<>"",'Release Calendar'!M9,"") -> Completed | E9: =IF(AND(Q9<>"",R9<>"",DATE(2026,2,0)>=Q9,DATE(2026,1,1)<=R9),"█","") | F9: =IF(AND(Q9<>"",R9<>"",DATE(2026,3,0)>=Q9,DATE(2026,2,1)<=R9),"█","") | G9: =IF(AND(Q9<>"",R9<>"",DATE(2026,4,0)>=Q9,DATE(2026,3,1)<=R9),"█","") | H9: =IF(AND(Q9<>"",R9<>"",DATE(2026,5,0)>=Q9,DATE(2026,4,1)<=R9),"█","") | I9: =IF(AND(Q9<>"",R9<>"",DATE(2026,6,0)>=Q9,DATE(2026,5,1)<=R9),"█","") | J9: =IF(AND(Q9<>"",R9<>"",DATE(2026,7,0)>=Q9,DATE(2026,6,1)<=R9),"█","") | K9: =IF(AND(Q9<>"",R9<>"",DATE(2026,8,0)>=Q9,DATE(2026,7,1)<=R9),"█","") | L9: =IF(AND(Q9<>"",R9<>"",DATE(2026,9,0)>=Q9,DATE(2026,8,1)<=R9),"█","") -> █ | M9: =IF(AND(Q9<>"",R9<>"",DATE(2026,10,0)>=Q9,DATE(2026,9,1)<=R9),"█","") | N9: =IF(AND(Q9<>"",R9<>"",DATE(2026,11,0)>=Q9,DATE(2026,10,1)<=R9),"█","") | O9: =IF(AND(Q9<>"",R9<>"",DATE(2026,12,0)>=Q9,DATE(2026,11,1)<=R9),"█","") | P9: =IF(AND(Q9<>"",R9<>"",DATE(2026,12,31)>=Q9,DATE(2026,12,1)<=R9),"█","") | Q9: =IF('Release Calendar'!I9<>"",'Release Calendar'!I9,"") -> 46251 | R9: =IF('Release Calendar'!J9<>"",'Release Calendar'!J9,"") -> 46251
A10: 6 | B10: =IF('Release Calendar'!B10<>"",'Release Calendar'!B10,"") -> BVS Sales Old Age flag Semantic | C10: =IF('Release Calendar'!K10<>"",'Release Calendar'!K10,"") -> Production | D10: =IF('Release Calendar'!M10<>"",'Release Calendar'!M10,"") -> Completed | E10: =IF(AND(Q10<>"",R10<>"",DATE(2026,2,0)>=Q10,DATE(2026,1,1)<=R10),"█","") | F10: =IF(AND(Q10<>"",R10<>"",DATE(2026,3,0)>=Q10,DATE(2026,2,1)<=R10),"█","") | G10: =IF(AND(Q10<>"",R10<>"",DATE(2026,4,0)>=Q10,DATE(2026,3,1)<=R10),"█","") | H10: =IF(AND(Q10<>"",R10<>"",DATE(2026,5,0)>=Q10,DATE(2026,4,1)<=R10),"█","") | I10: =IF(AND(Q10<>"",R10<>"",DATE(2026,6,0)>=Q10,DATE(2026,5,1)<=R10),"█","") | J10: =IF(AND(Q10<>"",R10<>"",DATE(2026,7,0)>=Q10,DATE(2026,6,1)<=R10),"█","") | K10: =IF(AND(Q10<>"",R10<>"",DATE(2026,8,0)>=Q10,DATE(2026,7,1)<=R10),"█","") | L10: =IF(AND(Q10<>"",R10<>"",DATE(2026,9,0)>=Q10,DATE(2026,8,1)<=R10),"█","") -> █ | M10: =IF(AND(Q10<>"",R10<>"",DATE(2026,10,0)>=Q10,DATE(2026,9,1)<=R10),"█","") | N10: =IF(AND(Q10<>"",R10<>"",DATE(2026,11,0)>=Q10,DATE(2026,10,1)<=R10),"█","") | O10: =IF(AND(Q10<>"",R10<>"",DATE(2026,12,0)>=Q10,DATE(2026,11,1)<=R10),"█","") | P10: =IF(AND(Q10<>"",R10<>"",DATE(2026,12,31)>=Q10,DATE(2026,12,1)<=R10),"█","") | Q10: =IF('Release Calendar'!I10<>"",'Release Calendar'!I10,"") -> 46246 | R10: =IF('Release Calendar'!J10<>"",'Release Calendar'!J10,"") -> 46253
A11: 7 | B11: =IF('Release Calendar'!B11<>"",'Release Calendar'!B11,"") -> UCIP_LKP update | C11: =IF('Release Calendar'!K11<>"",'Release Calendar'!K11,"") -> Production | D11: =IF('Release Calendar'!M11<>"",'Release Calendar'!M11,"") -> Completed | E11: =IF(AND(Q11<>"",R11<>"",DATE(2026,2,0)>=Q11,DATE(2026,1,1)<=R11),"█","") | F11: =IF(AND(Q11<>"",R11<>"",DATE(2026,3,0)>=Q11,DATE(2026,2,1)<=R11),"█","") | G11: =IF(AND(Q11<>"",R11<>"",DATE(2026,4,0)>=Q11,DATE(2026,3,1)<=R11),"█","") | H11: =IF(AND(Q11<>"",R11<>"",DATE(2026,5,0)>=Q11,DATE(2026,4,1)<=R11),"█","") | I11: =IF(AND(Q11<>"",R11<>"",DATE(2026,6,0)>=Q11,DATE(2026,5,1)<=R11),"█","") | J11: =IF(AND(Q11<>"",R11<>"",DATE(2026,7,0)>=Q11,DATE(2026,6,1)<=R11),"█","") | K11: =IF(AND(Q11<>"",R11<>"",DATE(2026,8,0)>=Q11,DATE(2026,7,1)<=R11),"█","") | L11: =IF(AND(Q11<>"",R11<>"",DATE(2026,9,0)>=Q11,DATE(2026,8,1)<=R11),"█","") -> █ | M11: =IF(AND(Q11<>"",R11<>"",DATE(2026,10,0)>=Q11,DATE(2026,9,1)<=R11),"█","") | N11: =IF(AND(Q11<>"",R11<>"",DATE(2026,11,0)>=Q11,DATE(2026,10,1)<=R11),"█","") | O11: =IF(AND(Q11<>"",R11<>"",DATE(2026,12,0)>=Q11,DATE(2026,11,1)<=R11),"█","") | P11: =IF(AND(Q11<>"",R11<>"",DATE(2026,12,31)>=Q11,DATE(2026,12,1)<=R11),"█","") | Q11: =IF('Release Calendar'!I11<>"",'Release Calendar'!I11,"") -> 46252 | R11: =IF('Release Calendar'!J11<>"",'Release Calendar'!J11,"") -> 46253
A12: 8 | B12: =IF('Release Calendar'!B12<>"",'Release Calendar'!B12,"") -> Daily Kpi Report - Addition of KPIs | C12: =IF('Release Calendar'!K12<>"",'Release Calendar'!K12,"") -> Production | D12: =IF('Release Calendar'!M12<>"",'Release Calendar'!M12,"") -> Completed | E12: =IF(AND(Q12<>"",R12<>"",DATE(2026,2,0)>=Q12,DATE(2026,1,1)<=R12),"█","") | F12: =IF(AND(Q12<>"",R12<>"",DATE(2026,3,0)>=Q12,DATE(2026,2,1)<=R12),"█","") | G12: =IF(AND(Q12<>"",R12<>"",DATE(2026,4,0)>=Q12,DATE(2026,3,1)<=R12),"█","") | H12: =IF(AND(Q12<>"",R12<>"",DATE(2026,5,0)>=Q12,DATE(2026,4,1)<=R12),"█","") | I12: =IF(AND(Q12<>"",R12<>"",DATE(2026,6,0)>=Q12,DATE(2026,5,1)<=R12),"█","") | J12: =IF(AND(Q12<>"",R12<>"",DATE(2026,7,0)>=Q12,DATE(2026,6,1)<=R12),"█","") | K12: =IF(AND(Q12<>"",R12<>"",DATE(2026,8,0)>=Q12,DATE(2026,7,1)<=R12),"█","") | L12: =IF(AND(Q12<>"",R12<>"",DATE(2026,9,0)>=Q12,DATE(2026,8,1)<=R12),"█","") | M12: =IF(AND(Q12<>"",R12<>"",DATE(2026,10,0)>=Q12,DATE(2026,9,1)<=R12),"█","") -> █ | N12: =IF(AND(Q12<>"",R12<>"",DATE(2026,11,0)>=Q12,DATE(2026,10,1)<=R12),"█","") | O12: =IF(AND(Q12<>"",R12<>"",DATE(2026,12,0)>=Q12,DATE(2026,11,1)<=R12),"█","") | P12: =IF(AND(Q12<>"",R12<>"",DATE(2026,12,31)>=Q12,DATE(2026,12,1)<=R12),"█","") | Q12: =IF('Release Calendar'!I12<>"",'Release Calendar'!I12,"") -> 46267 | R12: =IF('Release Calendar'!J12<>"",'Release Calendar'!J12,"") -> 46267
A13: 9 | B13: =IF('Release Calendar'!B13<>"",'Release Calendar'!B13,"") -> Reward Hub Ceo Category | C13: =IF('Release Calendar'!K13<>"",'Release Calendar'!K13,"") -> Production | D13: =IF('Release Calendar'!M13<>"",'Release Calendar'!M13,"") -> Completed | E13: =IF(AND(Q13<>"",R13<>"",DATE(2026,2,0)>=Q13,DATE(2026,1,1)<=R13),"█","") | F13: =IF(AND(Q13<>"",R13<>"",DATE(2026,3,0)>=Q13,DATE(2026,2,1)<=R13),"█","") | G13: =IF(AND(Q13<>"",R13<>"",DATE(2026,4,0)>=Q13,DATE(2026,3,1)<=R13),"█","") | H13: =IF(AND(Q13<>"",R13<>"",DATE(2026,5,0)>=Q13,DATE(2026,4,1)<=R13),"█","") | I13: =IF(AND(Q13<>"",R13<>"",DATE(2026,6,0)>=Q13,DATE(2026,5,1)<=R13),"█","") | J13: =IF(AND(Q13<>"",R13<>"",DATE(2026,7,0)>=Q13,DATE(2026,6,1)<=R13),"█","") | K13: =IF(AND(Q13<>"",R13<>"",DATE(2026,8,0)>=Q13,DATE(2026,7,1)<=R13),"█","") | L13: =IF(AND(Q13<>"",R13<>"",DATE(2026,9,0)>=Q13,DATE(2026,8,1)<=R13),"█","") | M13: =IF(AND(Q13<>"",R13<>"",DATE(2026,10,0)>=Q13,DATE(2026,9,1)<=R13),"█","") -> █ | N13: =IF(AND(Q13<>"",R13<>"",DATE(2026,11,0)>=Q13,DATE(2026,10,1)<=R13),"█","") | O13: =IF(AND(Q13<>"",R13<>"",DATE(2026,12,0)>=Q13,DATE(2026,11,1)<=R13),"█","") | P13: =IF(AND(Q13<>"",R13<>"",DATE(2026,12,31)>=Q13,DATE(2026,12,1)<=R13),"█","") | Q13: =IF('Release Calendar'!I13<>"",'Release Calendar'!I13,"") -> 46266 | R13: =IF('Release Calendar'!J13<>"",'Release Calendar'!J13,"") -> 46269
A14: 10 | B14: =IF('Release Calendar'!B14<>"",'Release Calendar'!B14,"") -> Daily KPI Report- Addition of App Kpis | C14: =IF('Release Calendar'!K14<>"",'Release Calendar'!K14,"") -> Completed | D14: =IF('Release Calendar'!M14<>"",'Release Calendar'!M14,"") -> Completed | E14: =IF(AND(Q14<>"",R14<>"",DATE(2026,2,0)>=Q14,DATE(2026,1,1)<=R14),"█","") | F14: =IF(AND(Q14<>"",R14<>"",DATE(2026,3,0)>=Q14,DATE(2026,2,1)<=R14),"█","") | G14: =IF(AND(Q14<>"",R14<>"",DATE(2026,4,0)>=Q14,DATE(2026,3,1)<=R14),"█","") | H14: =IF(AND(Q14<>"",R14<>"",DATE(2026,5,0)>=Q14,DATE(2026,4,1)<=R14),"█","") | I14: =IF(AND(Q14<>"",R14<>"",DATE(2026,6,0)>=Q14,DATE(2026,5,1)<=R14),"█","") | J14: =IF(AND(Q14<>"",R14<>"",DATE(2026,7,0)>=Q14,DATE(2026,6,1)<=R14),"█","") | K14: =IF(AND(Q14<>"",R14<>"",DATE(2026,8,0)>=Q14,DATE(2026,7,1)<=R14),"█","") | L14: =IF(AND(Q14<>"",R14<>"",DATE(2026,9,0)>=Q14,DATE(2026,8,1)<=R14),"█","") | M14: =IF(AND(Q14<>"",R14<>"",DATE(2026,10,0)>=Q14,DATE(2026,9,1)<=R14),"█","") -> █ | N14: =IF(AND(Q14<>"",R14<>"",DATE(2026,11,0)>=Q14,DATE(2026,10,1)<=R14),"█","") | O14: =IF(AND(Q14<>"",R14<>"",DATE(2026,12,0)>=Q14,DATE(2026,11,1)<=R14),"█","") | P14: =IF(AND(Q14<>"",R14<>"",DATE(2026,12,31)>=Q14,DATE(2026,12,1)<=R14),"█","") | Q14: =IF('Release Calendar'!I14<>"",'Release Calendar'!I14,"") -> 46274 | R14: =IF('Release Calendar'!J14<>"",'Release Calendar'!J14,"") -> 46274
A15: 11 | B15: =IF('Release Calendar'!B15<>"",'Release Calendar'!B15,"") -> Postpaid lifecycle DDLS fix | C15: =IF('Release Calendar'!K15<>"",'Release Calendar'!K15,"") -> Production | D15: =IF('Release Calendar'!M15<>"",'Release Calendar'!M15,"") -> Completed | E15: =IF(AND(Q15<>"",R15<>"",DATE(2026,2,0)>=Q15,DATE(2026,1,1)<=R15),"█","") | F15: =IF(AND(Q15<>"",R15<>"",DATE(2026,3,0)>=Q15,DATE(2026,2,1)<=R15),"█","") | G15: =IF(AND(Q15<>"",R15<>"",DATE(2026,4,0)>=Q15,DATE(2026,3,1)<=R15),"█","") | H15: =IF(AND(Q15<>"",R15<>"",DATE(2026,5,0)>=Q15,DATE(2026,4,1)<=R15),"█","") | I15: =IF(AND(Q15<>"",R15<>"",DATE(2026,6,0)>=Q15,DATE(2026,5,1)<=R15),"█","") | J15: =IF(AND(Q15<>"",R15<>"",DATE(2026,7,0)>=Q15,DATE(2026,6,1)<=R15),"█","") | K15: =IF(AND(Q15<>"",R15<>"",DATE(2026,8,0)>=Q15,DATE(2026,7,1)<=R15),"█","") | L15: =IF(AND(Q15<>"",R15<>"",DATE(2026,9,0)>=Q15,DATE(2026,8,1)<=R15),"█","") | M15: =IF(AND(Q15<>"",R15<>"",DATE(2026,10,0)>=Q15,DATE(2026,9,1)<=R15),"█","") -> █ | N15: =IF(AND(Q15<>"",R15<>"",DATE(2026,11,0)>=Q15,DATE(2026,10,1)<=R15),"█","") | O15: =IF(AND(Q15<>"",R15<>"",DATE(2026,12,0)>=Q15,DATE(2026,11,1)<=R15),"█","") | P15: =IF(AND(Q15<>"",R15<>"",DATE(2026,12,31)>=Q15,DATE(2026,12,1)<=R15),"█","") | Q15: =IF('Release Calendar'!I15<>"",'Release Calendar'!I15,"") -> 46274 | R15: =IF('Release Calendar'!J15<>"",'Release Calendar'!J15,"") -> 46274
A16: 12 | B16: =IF('Release Calendar'!B16<>"",'Release Calendar'!B16,"") -> Jazz Advance TPT Update | C16: =IF('Release Calendar'!K16<>"",'Release Calendar'!K16,"") -> Completed | D16: =IF('Release Calendar'!M16<>"",'Release Calendar'!M16,"") -> Completed | E16: =IF(AND(Q16<>"",R16<>"",DATE(2026,2,0)>=Q16,DATE(2026,1,1)<=R16),"█","") | F16: =IF(AND(Q16<>"",R16<>"",DATE(2026,3,0)>=Q16,DATE(2026,2,1)<=R16),"█","") | G16: =IF(AND(Q16<>"",R16<>"",DATE(2026,4,0)>=Q16,DATE(2026,3,1)<=R16),"█","") | H16: =IF(AND(Q16<>"",R16<>"",DATE(2026,5,0)>=Q16,DATE(2026,4,1)<=R16),"█","") | I16: =IF(AND(Q16<>"",R16<>"",DATE(2026,6,0)>=Q16,DATE(2026,5,1)<=R16),"█","") | J16: =IF(AND(Q16<>"",R16<>"",DATE(2026,7,0)>=Q16,DATE(2026,6,1)<=R16),"█","") | K16: =IF(AND(Q16<>"",R16<>"",DATE(2026,8,0)>=Q16,DATE(2026,7,1)<=R16),"█","") | L16: =IF(AND(Q16<>"",R16<>"",DATE(2026,9,0)>=Q16,DATE(2026,8,1)<=R16),"█","") -> █ | M16: =IF(AND(Q16<>"",R16<>"",DATE(2026,10,0)>=Q16,DATE(2026,9,1)<=R16),"█","") | N16: =IF(AND(Q16<>"",R16<>"",DATE(2026,11,0)>=Q16,DATE(2026,10,1)<=R16),"█","") | O16: =IF(AND(Q16<>"",R16<>"",DATE(2026,12,0)>=Q16,DATE(2026,11,1)<=R16),"█","") | P16: =IF(AND(Q16<>"",R16<>"",DATE(2026,12,31)>=Q16,DATE(2026,12,1)<=R16),"█","") | Q16: =IF('Release Calendar'!I16<>"",'Release Calendar'!I16,"") -> 46265 | R16: =IF('Release Calendar'!J16<>"",'Release Calendar'!J16,"") -> 46265
... A504: 500 | B504: =IF('Release Calendar'!B504<>"",'Release Calendar'!B504,"") | C504: =IF('Release Calendar'!K504<>"",'Release Calendar'!K504,"") | D504: =IF('Release Calendar'!M504<>"",'Release Calendar'!M504,"") | E504: =IF(AND(Q504<>"",R504<>"",DATE(2026,2,0)>=Q504,DATE(2026,1,1)<=R504),"█","") | F504: =IF(AND(Q504<>"",R504<>"",DATE(2026,3,0)>=Q504,DATE(2026,2,1)<=R504),"█","") | G504: =IF(AND(Q504<>"",R504<>"",DATE(2026,4,0)>=Q504,DATE(2026,3,1)<=R504),"█","") | H504: =IF(AND(Q504<>"",R504<>"",DATE(2026,5,0)>=Q504,DATE(2026,4,1)<=R504),"█","") | I504: =IF(AND(Q504<>"",R504<>"",DATE(2026,6,0)>=Q504,DATE(2026,5,1)<=R504),"█","") | J504: =IF(AND(Q504<>"",R504<>"",DATE(2026,7,0)>=Q504,DATE(2026,6,1)<=R504),"█","") | K504: =IF(AND(Q504<>"",R504<>"",DATE(2026,8,0)>=Q504,DATE(2026,7,1)<=R504),"█","") | L504: =IF(AND(Q504<>"",R504<>"",DATE(2026,9,0)>=Q504,DATE(2026,8,1)<=R504),"█","") | M504: =IF(AND(Q504<>"",R504<>"",DATE(2026,10,0)>=Q504,DATE(2026,9,1)<=R504),"█","") | N504: =IF(AND(Q504<>"",R504<>"",DATE(2026,11,0)>=Q504,DATE(2026,10,1)<=R504),"█","") | O504: =IF(AND(Q504<>"",R504<>"",DATE(2026,12,0)>=Q504,DATE(2026,11,1)<=R504),"█","") | P504: =IF(AND(Q504<>"",R504<>"",DATE(2026,12,31)>=Q504,DATE(2026,12,1)<=R504),"█","") | Q504: =IF('Release Calendar'!I504<>"",'Release Calendar'!I504,"") | R504: =IF('Release Calendar'!J504<>"",'Release Calendar'!J504,"")
A506: =" ★ Highlighted column = current month ("&TEXT(TODAY(),"mmm yyyy")&") | Gantt bars auto-update from Release Calendar dates" -> ★ Highlighted column = current month (Oct 2026) | Gantt bars auto-update from Release Calendar dates
A508: LEGEND
A509: █ On Track — on schedule | F509: █ At Risk — delays possible | K509: █ Delayed — behind schedule
A510: █ Completed — deployed | F510: █ On Hold — paused | K510: =" ★ Current month ("&TEXT(TODAY(),"mmm yyyy")&")" -> ★ Current month (Oct 2026)

Sheet Monthly Calendar
A1: TEKNOSYS · TELECOM DW | Monthly Release Calendar
A3: Jira-style month view · chips are pulled live from the Release Calendar sheet (Start / Target Deploy)
A4: Month: | B4: =MONTH(TODAY()) -> 10 | C4: Year: | D4: =YEAR(TODAY()) -> 2026 | E4: =TEXT(DATE($D$4,$B$4,1),"mmmm yyyy") -> October 2026 | I4: =DATE($D$4,$B$4,1) -> 46296 | J4: =WEEKDAY(I4,1) -> 5 | K4: =DAY(EOMONTH(I4,0)) -> 31
A5: SUN | B5: MON | C5: TUE | D5: WED | E5: THU | F5: FRI | G5: SAT
A6: =IF(AND((0*7+0-($J$4-1)+1)>=1,(0*7+0-($J$4-1)+1)<=$K$4),$I$4+(0*7+0-($J$4-1)+1)-1,"") | B6: =IF(AND((0*7+1-($J$4-1)+1)>=1,(0*7+1-($J$4-1)+1)<=$K$4),$I$4+(0*7+1-($J$4-1)+1)-1,"") | C6: =IF(AND((0*7+2-($J$4-1)+1)>=1,(0*7+2-($J$4-1)+1)<=$K$4),$I$4+(0*7+2-($J$4-1)+1)-1,"") | D6: =IF(AND((0*7+3-($J$4-1)+1)>=1,(0*7+3-($J$4-1)+1)<=$K$4),$I$4+(0*7+3-($J$4-1)+1)-1,"") | E6: =IF(AND((0*7+4-($J$4-1)+1)>=1,(0*7+4-($J$4-1)+1)<=$K$4),$I$4+(0*7+4-($J$4-1)+1)-1,"") -> 46296 | F6: =IF(AND((0*7+5-($J$4-1)+1)>=1,(0*7+5-($J$4-1)+1)<=$K$4),$I$4+(0*7+5-($J$4-1)+1)-1,"") -> 46297 | G6: =IF(AND((0*7+6-($J$4-1)+1)>=1,(0*7+6-($J$4-1)+1)<=$K$4),$I$4+(0*7+6-($J$4-1)+1)-1,"") -> 46298
A7: =IF(A6="","",IFERROR("● "&INDEX('Release Calendar'!$B$5:$B$504,MATCH(A6,'Release Calendar'!$I$5:$I$504,0))&" · Start ","")&IFERROR("● "&INDEX('Release Calendar'!$B$5:$B$504,MATCH(A6,'Release Calendar'!$J$5:$J$504,0))&" · Target ","")) | B7: =IF(B6="","",IFERROR("● "&INDEX('Release Calendar'!$B$5:$B$504,MATCH(B6,'Release Calendar'!$I$5:$I$504,0))&" · Start ","")&IFERROR("● "&INDEX('Release Calendar'!$B$5:$B$504,MATCH(B6,'Release Calendar'!$J$5:$J$504,0))&" · Target ","")) | C7: =IF(C6="","",IFERROR("● "&INDEX('Release Calendar'!$B$5:$B$504,MATCH(C6,'Release Calendar'!$I$5:$I$504,0))&" · Start ","")&IFERROR("● "&INDEX('Release Calendar'!$B$5:$B$504,MATCH(C6,'Release Calendar'!$J$5:$J$504,0))&" · Target ","")) | D7: =IF(D6="","",IFERROR("● "&INDEX('Release Calendar'!$B$5:$B$504,MATCH(D6,'Release Calendar'!$I$5:$I$504,0))&" · Start ","")&IFERROR("● "&INDEX('Release Calendar'!$B$5:$B$504,MATCH(D6,'Release Calendar'!$J$5:$J$504,0))&" · Target ","")) | E7: =IF(E6="","",IFERROR("● "&INDEX('Release Calendar'!$B$5:$B$504,MATCH(E6,'Release Calendar'!$I$5:$I$504,0))&" · Start ","")&IFERROR("● "&INDEX('Release Calendar'!$B$5:$B$504,MATCH(E6,'Release Calendar'!$J$5:$J$504,0))&" · Target ","")) | F7: =IF(F6="","",IFERROR("● "&INDEX('Release Calendar'!$B$5:$B$504,MATCH(F6,'Release Calendar'!$I$5:$I$504,0))&" · Start ","")&IFERROR("● "&INDEX('Release Calendar'!$B$5:$B$504,MATCH(F6,'Release Calendar'!$J$5:$J$504,0))&" · Target ","")) | G7: =IF(G6="","",IFERROR("● "&INDEX('Release Calendar'!$B$5:$B$504,MATCH(G6,'Release Calendar'!$I$5:$I$504,0))&" · Start ","")&IFERROR("● "&INDEX('Release Calendar'!$B$5:$B$504,MATCH(G6,'Release Calendar'!$J$5:$J$504,0))&" · Target ",""))
A8: =IF(AND((1*7+0-($J$4-1)+1)>=1,(1*7+0-($J$4-1)+1)<=$K$4),$I$4+(1*7+0-($J$4-1)+1)-1,"") -> 46299 | B8: =IF(AND((1*7+1-($J$4-1)+1)>=1,(1*7+1-($J$4-1)+1)<=$K$4),$I$4+(1*7+1-($J$4-1)+1)-1,"") -> 46300 | C8: =IF(AND((1*7+2-($J$4-1)+1)>=1,(1*7+2-($J$4-1)+1)<=$K$4),$I$4+(1*7+2-($J$4-1)+1)-1,"") -> 46301 | D8: =IF(AND((1*7+3-($J$4-1)+1)>=1,(1*7+3-($J$4-1)+1)<=$K$4),$I$4+(1*7+3-($J$4-1)+1)-1,"") -> 46302 | E8: =IF(AND((1*7+4-($J$4-1)+1)>=1,(1*7+4-($J$4-1)+1)<=$K$4),$I$4+(1*7+4-($J$4-1)+1)-1,"") -> 46303 | F8: =IF(AND((1*7+5-($J$4-1)+1)>=1,(1*7+5-($J$4-1)+1)<=$K$4),$I$4+(1*7+5-($J$4-1)+1)-1,"") -> 46304 | G8: =IF(AND((1*7+6-($J$4-1)+1)>=1,(1*7+6-($J$4-1)+1)<=$K$4),$I$4+(1*7+6-($J$4-1)+1)-1,"") -> 46305
A9: =IF(A8="","",IFERROR("● "&INDEX('Release Calendar'!$B$5:$B$504,MATCH(A8,'Release Calendar'!$I$5:$I$504,0))&" · Start ","")&IFERROR("● "&INDEX('Release Calendar'!$B$5:$B$504,MATCH(A8,'Release Calendar'!$J$5:$J$504,0))&" · Target ","")) | B9: =IF(B8="","",IFERROR("● "&INDEX('Release Calendar'!$B$5:$B$504,MATCH(B8,'Release Calendar'!$I$5:$I$504,0))&" · Start ","")&IFERROR("● "&INDEX('Release Calendar'!$B$5:$B$504,MATCH(B8,'Release Calendar'!$J$5:$J$504,0))&" · Target ","")) | C9: =IF(C8="","",IFERROR("● "&INDEX('Release Calendar'!$B$5:$B$504,MATCH(C8,'Release Calendar'!$I$5:$I$504,0))&" · Start ","")&IFERROR("● "&INDEX('Release Calendar'!$B$5:$B$504,MATCH(C8,'Release Calendar'!$J$5:$J$504,0))&" · Target ","")) | D9: =IF(D8="","",IFERROR("● "&INDEX('Release Calendar'!$B$5:$B$504,MATCH(D8,'Release Calendar'!$I$5:$I$504,0))&" · Start ","")&IFERROR("● "&INDEX('Release Calendar'!$B$5:$B$504,MATCH(D8,'Release Calendar'!$J$5:$J$504,0))&" · Target ","")) -> ● Tamasha IP list update · Start ● Tamasha IP list update · Target | E9: =IF(E8="","",IFERROR("● "&INDEX('Release Calendar'!$B$5:$B$504,MATCH(E8,'Release Calendar'!$I$5:$I$504,0))&" · Start ","")&IFERROR("● "&INDEX('Release Calendar'!$B$5:$B$504,MATCH(E8,'Release Calendar'!$J$5:$J$504,0))&" · Target ","")) | F9: =IF(F8="","",IFERROR("● "&INDEX('Release Calendar'!$B$5:$B$504,MATCH(F8,'Release Calendar'!$I$5:$I$504,0))&" · Start ","")&IFERROR("● "&INDEX('Release Calendar'!$B$5:$B$504,MATCH(F8,'Release Calendar'!$J$5:$J$504,0))&" · Target ","")) | G9: =IF(G8="","",IFERROR("● "&INDEX('Release Calendar'!$B$5:$B$504,MATCH(G8,'Release Calendar'!$I$5:$I$504,0))&" · Start ","")&IFERROR("● "&INDEX('Release Calendar'!$B$5:$B$504,MATCH(G8,'Release Calendar'!$J$5:$J$504,0))&" · Target ",""))
